<?xml version='1.0'?>
<robot name='my_robot'>
    <link name='base_link'>
        <visual>
            <geometry>
                <box size='0.6 0.3 0.3'/>
            </geometry>
            <material name='silver'>
                <color rgba='0.75 0.75 0.75 1'/>
            </material>
        </visual>
        <collision>
            <geometry>
                <box size='0.6 0.3 0.3'/>
            </geometry>
        </collision>
        <inertial>
            <mass value='1.0'/>
            <inertia ixx='0.015' iyy='0.0375' izz='0.0375'
                    ixy='0' ixz='0' iyz='0'/>
        </inertial>

    </link>

    <link name='rear_caster'>
        <visual>
            <geometry>
                <box size='0.1 0.1 0.3'/>
            </geometry>
            <material name='silver'>
                <color rgba='0.75 0.75 0.75 1'/>
            </material>
        </visual>
        <collision>
            <geometry>
                <box size='0.1 0.1 0.3'/>
            </geometry>
        </collision>
        <inertial>
            <mass value='0.1'/>
            <inertia ixx='0.00083' iyy='0.00083' izz='0.000167'
                    ixy='0' ixz='0' iyz='0'/>
        </inertial>
    </link>

    <joint name='rear_caster_joint' type='continuous'>
        <axis xyz='0 0 1'/>
        <parent link='base_link'/>
        <child link='rear_caster'/>
        <origin rpy='0 0 0' xyz='-0.3 0 0'/>
    </joint>

    <link name='rear_wheel'>
        <visual>
            <geometry>
                <cylinder length='0.05' radius='0.035'/>
            </geometry>
            <material name='white'>
                <color rgba='0 0 0 1'/>
            </material>
        </visual>
        <collision>
            <geometry>
                <cylinder length='0.05' radius='0.035'/>
            </geometry>
        </collision>
        <inertial>
            <mass value="0.1"/>
            <inertia ixx="5.1458e-5" iyy="5.1458e-5" izz="6.125e-5"
                        ixy="0" ixz="0" iyz="0"/>
        </inertial>
    </link>

    <joint name='rear_wheel_joint' type='continuous'>
        <axis xyz='0 0 1'/>
        <parent link='rear_caster'/>
        <child link='rear_wheel'/>
        <origin rpy='-1.5708 0 0' xyz = '0.05 0 -0.15'/>
    </joint>

    <link name='right_wheel'>
        <visual>
            <geometry>
                <cylinder length='0.05' radius='0.035'/>
            </geometry>
            <material name='black'>
                <color rgba='0 0 0 1'/>
            </material>
        </visual>
        <collision>
            <geometry>
                <cylinder length='0.05' radius='0.035'/>
            </geometry>
        </collision>
        <inertial>
            <mass value="0.1"/>
            <inertia ixx="5.1458e-5" iyy="5.1458e-5" izz="6.125e-5"
                        ixy="0" ixz="0" iyz="0"/>
        </inertial>        
    </link>

    <joint name='right_wheel_joint' type='continuous'>
        <axis xyz='0 0 1'/>
        <parent link='base_link'/>
        <child link='right_wheel'/>
        <origin rpy='1.5708 0 0' xyz='0.2825 -0.125 -0.15'/>
    </joint>

    <link name='left_wheel'>
        <visual>
            <geometry>
                <cylinder length='0.05' radius='0.035'/>
            </geometry>
            <material name='black'/>
        </visual>
        <collision>
            <geometry>
                <cylinder length='0.05' radius='0.035'/>
            </geometry>
        </collision>
        <inertial>
            <mass value="0.1"/>
            <inertia ixx="5.1458e-5" iyy="5.1458e-5" izz="6.125e-5"
                        ixy="0" ixz="0" iyz="0"/>
        </inertial>
    </link>

    <joint name='left_wheel_joint' type='continuous'>
        <axis xyz='0 0 1'/>
        <parent link='base_link'/>
        <child link='left_wheel'/>
        <origin rpy='1.5708 0 0' xyz='0.2825 0.125 -0.15'/>
    </joint>

    <link name='hokuyo_link'>
        <visual>
            <origin xyz='0 0 0' rpy='0 0 0'/>
            <geometry>
                <box size='0.1 0.1 0.1'/>
            </geometry>
            <material name='black'>
                <color rgba='0 0 0 1'/>
            </material>
        </visual>
        <collision>
            <origin xyz='0 0 0' rpy='0 0 0'/>
            <geometry>
                <box size='0.1 0.1 0.1'/>
            </geometry>
        </collision>
        <inertial>
            <mass value='1e-5'/>
            <origin xyz='0 0 0' rpy='0 0 0'/>
            <inertia ixx='1e-6' iyy='1e-6' izz='1e-6' 
                    ixz='0' ixy='0' iyz='0'/> 
        </inertial>
    </link>

    <joint name='hokuyo_joint' type='fixed'>
        <axis xyz='0 1 0'/>
        <origin xyz='0 0 0.2' rpy='0 0 0'/>
        <parent link='base_link'/>
        <child link='hokuyo_link'/>
    </joint>

    <link name='camera_link'>
        <visual>
            <origin xyz='0 0 0' rpy='0 0 0'/>
            <geometry>
                <box size='0.1 0.1 0.1'/>
            </geometry>
            <material name='black'/>
        </visual>
        <collision>
            <origin xyz='0 0 0' rpy='0 0 0'/>
            <geometry>
                <box size='0.1 0.1 0.1'/>
            </geometry>
            <material name='black'/>
        </collision>
        <inertial>
            <mass value='1e-5'/>
            <origin xyz='0 0 0' rpy='0 0 0'/>
            <inertia ixx='1e-6' iyy='1e-6' izz='1e-6' 
                    ixz='0' ixy='0' iyz='0'/> 
        </inertial>
    </link>

    <joint name='camera_joint' type='fixed'>
        <axis xyz='0 -1 0'/>
        <parent link='base_link'/>
        <child link='camera_link'/>
        <origin rpy='0 0 0' xyz='0.3 0 0.1'/>
    </joint>

    <gazebo>
        <plugin name='differential_drive_controller'
            filename='libgazebo_ros_diff_drive.so'>
            <leftJoint>left_wheel_joint</leftJoint>
            <rightJoint>right_wheel_joint</rightJoint>
            <robotBaseFrame>base_link</robotBaseFrame>
            <wheelSeparation>0.25</wheelSeparation>
            <wheelDiameter>0.07</wheelDiameter>
            <publishWheelJointState>true</publishWheelJointState>
        </plugin>
    </gazebo>

    <gazebo>
        <plugin name='joint_state_publisher'
                filename='libgazebo_ros_joint_state_publisher.so'>
            <jointName>rear_caster_joint, rear_wheel_joint</jointName>
        </plugin>
    </gazebo>

    <gazebo reference='hokuyo_link'>
        <sensor type='ray' name='hokuyo'>
            <pose>0 0 0 0 0 0</pose>
            <visualize>false</visualize>
            <update_rate>40</update_rate>
            <ray>
                <scan>
                    <horizontal>
                        <samples>720</samples>
                        <resolution>1</resolution>
                        <min_angle>-0.8</min_angle>
                        <max_angle>1.570796</max_angle>
                    </horizontal>
                </scan>
                <range>
                    <min>0.1</min>
                    <max>30.0</max>
                    <resolution>0.01</resolution>
                </range>
            </ray>
            <plugin name='laser' filename='libgazebo_ros_laser.so'>
                <topicName>/scan</topicName>
                <frameName>hokuyo_link</frameName>
            </plugin>
        </sensor>
    </gazebo>

    <gazebo reference="camera_link">
        <sensor type="camera" name="camera1">
          <update_rate>30.0</update_rate>
          <camera name="head">
            <horizontal_fov>1.3962634</horizontal_fov>
            <image>
              <width>800</width>
              <height>800</height>
              <format>R8G8B8</format>
            </image>
            <clip>
              <near>0.02</near>
              <far>300</far>
            </clip>
            <noise>
              <type>gaussian</type>
              <!-- Noise is sampled independently per pixel on each frame.
                   That pixel's noise value is added to each of its color
                   channels, which at that point lie in the range [0,1]. -->
              <mean>0.0</mean>
              <stddev>0.007</stddev>
            </noise>
          </camera>
          <plugin name="camera_controller" filename="libgazebo_ros_camera.so">
            <alwaysOn>true</alwaysOn>
            <updateRate>0.0</updateRate>
            <cameraName>rrbot/camera1</cameraName>
            <imageTopicName>image_raw</imageTopicName>
            <cameraInfoTopicName>camera_info</cameraInfoTopicName>
            <frameName>camera_link</frameName>
            <hackBaseline>0.07</hackBaseline>
            <distortionK1>0.0</distortionK1>
            <distortionK2>0.0</distortionK2>
            <distortionK3>0.0</distortionK3>
            <distortionT1>0.0</distortionT1>
            <distortionT2>0.0</distortionT2>
          </plugin>
        </sensor>
      </gazebo>

</robot>
